<?xml version="1.0" ?>
<robot name="human_arm">

<material name="silver">
  <color rgba="0.700 0.700 0.700 1.000"/>
</material>

<link name="base_link">
  <inertial>
    <origin xyz="0.0 0.0 0.0" rpy="0 0 0"/>
    <mass value="0.0"/>
    <inertia ixx="0.0" iyy="0.0" izz="0.0" ixy="0.0" iyz="0.0" ixz="0.0"/>
  </inertial>
</link>

<joint name="base_fixed" type="fixed">
  <origin rpy="0 0 0.0" xyz="0 0 0.0"/>
  <parent link="base_link"/>
  <child link="base_link_0"/>
  <axis xyz="0 0 0"/>
</joint>

<link name="base_link_0">
  <inertial>
    <origin xyz="0.0 0.0 0.0" rpy="0 0 0"/>
    <mass value="0.0"/>
    <inertia ixx="0.0" iyy="0.0" izz="0.0" ixy="0.0" iyz="0.0" ixz="0.0"/>
  </inertial>
</link>

<link name="base_link_1">
  <inertial>
    <origin xyz="0.0 0.0 0.0" rpy="0 0 0"/>
    <mass value="0.0"/>
    <inertia ixx="0.0" iyy="0.0" izz="0.0" ixy="0.0" iyz="0.0" ixz="0.0"/>
  </inertial>
</link>

<link name="base_link_2">
  <inertial>
    <origin xyz="0.0 0.0 0.0" rpy="0 0 0"/>
    <mass value="0.0"/>
    <inertia ixx="0.0" iyy="0.0" izz="0.0" ixy="0.0" iyz="0.0" ixz="0.0"/>
  </inertial>
</link>

<link name="upper_arm">
  <inertial>
    <origin xyz="0.00277 -0.00352 -0.098" rpy="0 0 0"/>
    <mass value="1.0"/>
    <inertia ixx="0.00691" iyy="0.00674" izz="0.00097" ixy="-6.65745e-06" iyz="-7.0718e-05" ixz="0.00015"/>
  </inertial>
  <visual>
    <origin xyz="0 0 0" rpy="0 0 0"/>
    <geometry>
      <mesh filename="upper.stl" scale="1.0 1.0 1.0"/>
    </geometry>
    <material name="silver"/>
    <material/>
  </visual>
  <collision>
    <origin xyz="0 0 0" rpy="0 0 0"/>
    <geometry>
      <mesh filename="upper.stl" scale="1.0 1.0 1.0"/>
    </geometry>
  </collision>
</link>

<link name="lower_arm">
  <inertial>
    <origin xyz="0.01457 9.28389e-05 -0.19143" rpy="0 0 0"/>
    <mass value="1.0"/>
    <inertia ixx="0.01712" iyy="0.01699" izz="0.00072" ixy="-5.34657e-05" iyz="-0.00071" ixz="0.00031"/>
  </inertial>
  <visual>
    <origin xyz="0.0 0.0 0.0" rpy="0 0 0"/>
    <geometry>
      <mesh filename="lower.stl" scale="1.0 1.0 1.0"/>
    </geometry>
    <material name="silver"/>
    <material/>
  </visual>
  <collision>
    <origin xyz="0.0 0.0 0.0" rpy="0 0 0"/>
    <geometry>
      <mesh filename="lower.stl" scale="1.0 1.0 1.0"/>
    </geometry>
  </collision>
</link>

<joint name="base_x" type="revolute">
  <origin xyz="0.0 0.0 0.0" rpy="0 0 0"/>
  <parent link="base_link_0"/>
  <child link="base_link_1"/>
  <axis xyz="1.0 0.0 0.0"/>
  <limit effort="100" lower="-1.57" upper="1.57" velocity="5.0"/>
</joint>

<joint name="base_y" type="revolute">
  <origin xyz="0.0 0.0 0.0" rpy="0 0 0"/>
  <parent link="base_link_1"/>
  <child link="base_link_2"/>
  <axis xyz="0.0 1.0 0.0"/>
  <limit effort="100" lower="-1.57" upper="0" velocity="5.0"/>
</joint>

<joint name="base_z" type="revolute">
  <origin xyz="0.0 0.0 0.0" rpy="0 0 0"/>
  <parent link="base_link_2"/>
  <child link="upper_arm"/>
  <axis xyz="0.0 0.0 1.0"/>
  <limit effort="100" lower="0.0" upper="1.57" velocity="5.0"/>
</joint>

<joint name="upper_to_lower" type="revolute">
  <origin xyz="0.0 0.0 -0.24102" rpy="0 0 0"/>
  <parent link="upper_arm"/>
  <child link="lower_arm"/>
  <axis xyz="1.0 0.0 0.0"/>
  <limit effort="100" lower="-2.0944" upper="0.0" velocity="5.0"/>
</joint>

<joint name="grasp_fixed_joint" type="fixed">
    <parent link="lower_arm"/>
    <child link="ee_link"/>
    <!--origin rpy="0.0 0.0 1.570796325" xyz="0.0 0.0922 0.0"/-->
    <!--origin rpy="-1.57 0.0 1.57" xyz="0.0 0. 0.0"/-->
    <origin rpy="0.0 0.0 0.0" xyz="0.07 0.0 -0.27"/> 
</joint>

<link name="ee_link">
  <inertial>
    <origin xyz="0.0 0.0 0.0" rpy="0 0 0"/>
    <mass value="0.0"/>
    <inertia ixx="0.0" iyy="0.0" izz="0.0" ixy="0.0" iyz="0.0" ixz="0.0"/>
  </inertial>
  <visual>
    <geometry>
      <box size="0.01 0.01 0.01"/>
    </geometry>
    <origin rpy="0 0 0" xyz="0.0 0 0"/>
  </visual>
  <!-- <collision>
    <geometry>
      <box size="0.01 0.01 0.01"/>
    </geometry>
    <origin rpy="0 0 0" xyz="0.0 0 0"/>
  </collision> -->
</link>

</robot>
